<mujoco model="Adroit">
  <compiler angle="radian"/>
  <option apirate="200" iterations="20" noslip_iterations="20" cone="elliptic" solver="PGS"/>
  <size njmax="2000" nconmax="500" nstack="600000" nuser_body="9" nuser_jnt="1" nuser_site="1" nuser_tendon="1"
        nuser_actuator="16" nuser_sensor="1"/>
  <default class="main">
    <default class="D_Touch">
      <site size="0.009 0.004 0.013" group="4" type="box" rgba="0.8 0.8 0.8 0.15"/>
    </default>
    <default class="DC_Hand">
      <geom conaffinity="0" group="4" material="MatColl" friction="1 0.5 0.01" margin="0.0005"/>
    </default>
    <default class="D_Vizual">
      <geom type="mesh" contype="0" conaffinity="0" group="1" material="MatViz" friction="1 0.5 0.01" margin="0.0005"/>
    </default>
  </default>
  <asset>
    <material name="MatColl" specular="1" shininess="0.3" reflectance="0.5" rgba="0.4 0.5 0.6 1"/>
    <material name="MatViz" specular="0.75" shininess="0.1" reflectance="0.5" rgba="0.9 0.7 0.5 1"/>
    <mesh file="meshes/forearm_simple.stl" name="forearm_simple" scale="1 1 1"/>
    <mesh file="meshes/wrist.stl" name="wrist" scale="0.001 0.001 0.001"/>
    <mesh file="meshes/palm.stl" name="palm" scale="0.001 0.001 0.001"/>
    <mesh file="meshes/lfmetacarpal.stl" name="lfmetacarpal" scale="0.001 0.001 0.001"/>
    <mesh file="meshes/knuckle.stl" name="knuckle" scale="0.001 0.001 0.001"/>
    <mesh file="meshes/F3.stl" name="F3" scale="0.001 0.001 0.001"/>
    <mesh file="meshes/F2.stl" name="F2" scale="0.001 0.001 0.001"/>
    <mesh file="meshes/F1.stl" name="F1" scale="0.001 0.001 0.001"/>
    <mesh file="meshes/TH3_z.stl" name="TH3_z" scale="0.001 0.001 0.001"/>
    <mesh file="meshes/TH2_z.stl" name="TH2_z" scale="0.001 0.001 0.001"/>
    <mesh file="meshes/TH1_z.stl" name="TH1_z" scale="0.001 0.001 0.001"/>
  </asset>
  <worldbody>
    <body name="forearm" pos="0 -0.7 0.2" quat="0.000563312 -0.000562864 0.706825 0.707388">
      <inertial pos="0.001 -0.002 0.29" quat="0.982037 -0.0160006 0 -0.188007" mass="4" diaginertia="0.01 0.01 0.0075"/>
      <joint name="ARTx" pos="0 0 0" axis="1 0 0" type="slide" range="-0.25 0.25" damping="20" limited="true"
             margin="0.01" armature="0.001" frictionloss="0.001"/>
      <joint name="ARTy" pos="0 0 0" axis="0 1 0" type="slide" range="0 0.2" damping="20" limited="true" margin="0.01"
             armature="0.001" frictionloss="0.001"/>
      <joint name="ARTz" pos="0 0 0" axis="0 0 1" type="slide" range="-0.3 0.5" damping="20" limited="true"
             margin="0.01" armature="0.001" frictionloss="0.001"/>
      <joint name="ARRx" pos="0 0 0" axis="1 0 0" range="-0.75 0.75" damping="20" limited="true" margin="0.01"
             armature="0.001" frictionloss="0.001"/>
      <joint name="ARRy" pos="0 0 0" axis="0 1 0" range="-0.75 0.75" damping="20" limited="true" margin="0.01"
             armature="0.001" frictionloss="0.001"/>
      <joint name="ARRz" pos="0 0 0" axis="0 0 1" range="-0.75 0.75" damping="20" limited="true" margin="0.01"
             armature="0.001" frictionloss="0.001"/>
      <geom name="V_forearm" class="D_Vizual" pos="0 -0.01 0.181" quat="0.707388 0 0 -0.706825" mesh="forearm_simple"/>
      <geom name="C_forearm1" class="DC_Hand" size="0.08 0.053" pos="0 0 0.29" type="capsule" rgba="0.4 0.5 0.6 0.1"/>
      <body name="wrist" pos="0 0 0.396">
        <inertial pos="0.003 0 0.016" quat="0.504234 0.49623 0.49523 0.504234" mass="0.3"
                  diaginertia="0.001 0.001 0.001"/>
        <joint name="WRJ1" pos="0 0 0" axis="0 1 0" range="-0.524 0.175" armature="0.005" damping="0.5" user="1123"
               limited="true" margin="0.01" frictionloss="0.001"/>
        <geom name="V_wrist" class="D_Vizual" mesh="wrist"/>
        <geom name="C_wrist" class="DC_Hand" size="0.025 0.02" quat="0.707107 0.707107 0 0" type="capsule"
              rgba="0.4 0.5 0.6 0.1"/>
        <body name="palm" pos="0 0 0.034">
          <inertial pos="0.006 0 0.036" quat="0.715833 0.0439898 0.0749825 0.692839" mass="0.3"
                    diaginertia="0.001 0.001 0.001"/>
          <joint name="WRJ0" pos="0 0 0" axis="1 0 0" range="-0.785 0.611" user="1122"
                 limited="true" margin="0.01" armature="0.001" damping="0.05" frictionloss="0.001"/>
          <geom name="V_palm" class="D_Vizual" mesh="palm"/>
          <geom name="C_palm0" class="DC_Hand" size="0.052 0.015 0.06" pos="-0.008 0 0.038" type="box"
                rgba="0.4 0.5 0.6 0.1"/>
          <geom name="C_palm1" class="DC_Hand" size="0.011 0.0111 0.025" pos="-0.032 0 0.014" type="box"
                rgba="0.4 0.5 0.6 0.1"/>
          <site name="S_grasp" pos="0.007 -0.05 0.07" quat="0.00863043 -0.595202 -0.00337281 -0.803523" size="0.01"
                rgba="0 0 0 0"/>
          <site name="Tch_ffmetacarpal" class="D_Touch" pos="0.033 -0.008 0.078" size="0.009 0.004 0.006"/>
          <site name="Tch_mfmetacarpal" class="D_Touch" pos="0.011 -0.008 0.074" size="0.009 0.004 0.014"/>
          <site name="Tch_rfmetacarpal" class="D_Touch" pos="-0.011 -0.008 0.068" size="0.009 0.004 0.016"/>
          <site name="Tch_thmetacarpal" class="D_Touch" pos="0.006 -0.008 0.042" quat="0.959662 0 0.281157 0"
                size="0.008 0.004 0.015"/>
          <site name="Tch_palm" class="D_Touch" pos="-0.017 -0.008 0.024" quat="0.877583 0 -0.479426 0"
                size="0.012 0.004 0.016"/>
          <body name="ffknuckle" pos="0.033 0 0.095">
            <inertial pos="0 0 0" quat="0.520062 0.854102 0.00600072 -0.00300036" mass="0.008"
                      diaginertia="1e-05 1e-05 1e-05"/>
            <joint name="FFJ3" pos="0 0 0" axis="0 1 0" range="-0.436 0.436" user="1103" limited="true" margin="0.01"
                   armature="0.001" damping="0.05" frictionloss="0.001"/>
            <geom name="V_ffknuckle" class="D_Vizual" mesh="knuckle"/>
            <body name="ffproximal" pos="0 0 0">
              <inertial pos="0 0 0.023" quat="0.707095 -0.00400054 0.00400054 0.707095" mass="0.014"
                        diaginertia="1e-05 1e-05 1e-05"/>
              <joint name="FFJ2" pos="0 0 0" axis="1 0 0" range="0 1.571" user="1102" limited="true" margin="0.01"
                     armature="0.001" damping="0.05" frictionloss="0.001"/>
              <geom name="V_ffproximal" class="D_Vizual" mesh="F3"/>
              <geom name="C_ffproximal" class="DC_Hand" size="0.01 0.0225" pos="0 0 0.0225" type="capsule"/>
              <site name="Tch_ffproximal" class="D_Touch" pos="0 -0.007 0.022" size="0.009 0.004 0.012"/>
              <body name="ffmiddle" pos="0 0 0.045">
                <inertial pos="0 0 0.011" quat="0.707107 0 0 0.707107" mass="0.012" diaginertia="1e-05 1e-05 1e-05"/>
                <joint name="FFJ1" pos="0 0 0" axis="1 0 0" range="0 1.571" user="1101" limited="true" margin="0.01"
                       armature="0.001" damping="0.05" frictionloss="0.001"/>
                <geom name="V_ffmiddle" class="D_Vizual" mesh="F2"/>
                <geom name="C_ffmiddle" class="DC_Hand" size="0.00805 0.0125" pos="0 0 0.0125" type="capsule"/>
                <site name="Tch_ffmiddle" class="D_Touch" pos="0 -0.007 0.013" size="0.009 0.002 0.007"/>
                <body name="ffdistal" pos="0 0 0.025">
                  <inertial pos="0 0 0.015" quat="0.7071 -0.00300043 0.00300043 0.7071" mass="0.01"
                            diaginertia="1e-05 1e-05 1e-05"/>
                  <joint name="FFJ0" pos="0 0 0" axis="1 0 0" range="0 1.571" user="1100" limited="true" margin="0.01"
                         armature="0.001" damping="0.05" frictionloss="0.001"/>
                  <geom name="V_ffdistal" class="D_Vizual" pos="0 0 0.001" mesh="F1"/>
                  <geom name="C_ffdistal" class="DC_Hand" size="0.00705 0.012" pos="0 0 0.012" type="capsule"
                        condim="4"/>
                  <site name="S_fftip" pos="0 0 0.026" group="3" size="0.005 0 0" rgba="0.4 0.9 0.4 1"/>
                  <site name="Tch_fftip" class="D_Touch" pos="0 -0.004 0.018"/>
                </body>
              </body>
            </body>
          </body>
          <body name="mfknuckle" pos="0.011 0 0.099">
            <inertial pos="0 0 0" quat="0.520062 0.854102 0.00600072 -0.00300036" mass="0.008"
                      diaginertia="1e-05 1e-05 1e-05"/>
            <joint name="MFJ3" pos="0 0 0" axis="0 1 0" range="-0.436 0.436" user="1107" limited="true" margin="0.01"
                   armature="0.001" damping="0.05" frictionloss="0.001"/>
            <geom name="V_mfknuckle" class="D_Vizual" mesh="knuckle"/>
            <body name="mfproximal" pos="0 0 0">
              <inertial pos="0 0 0.023" quat="0.707095 -0.00400054 0.00400054 0.707095" mass="0.014"
                        diaginertia="1e-05 1e-05 1e-05"/>
              <joint name="MFJ2" pos="0 0 0" axis="1 0 0" range="0 1.571" user="1106" limited="true" margin="0.01"
                     armature="0.001" damping="0.05" frictionloss="0.001"/>
              <geom name="V_mfproximal" class="D_Vizual" mesh="F3"/>
              <geom name="C_mfproximal" class="DC_Hand" size="0.01 0.0225" pos="0 0 0.0225" type="capsule"/>
              <site name="Tch_mfproximal" class="D_Touch" pos="0 -0.007 0.022" size="0.009 0.004 0.012"/>
              <body name="mfmiddle" pos="0 0 0.045">
                <inertial pos="0 0 0.012" quat="0.707107 0 0 0.707107" mass="0.012" diaginertia="1e-05 1e-05 1e-05"/>
                <joint name="MFJ1" pos="0 0 0" axis="1 0 0" range="0 1.571" user="1105" limited="true" margin="0.01"
                       armature="0.001" damping="0.05" frictionloss="0.001"/>
                <geom name="V_mfmiddle" class="D_Vizual" mesh="F2"/>
                <geom name="C_mfmiddle" class="DC_Hand" size="0.00805 0.0125" pos="0 0 0.0125" type="capsule"/>
                <site name="Tch_mfmiddle" class="D_Touch" pos="0 -0.007 0.013" size="0.009 0.002 0.007"/>
                <body name="mfdistal" pos="0 0 0.025">
                  <inertial pos="0 0 0.015" quat="0.7071 -0.00300043 0.00300043 0.7071" mass="0.01"
                            diaginertia="1e-05 1e-05 1e-05"/>
                  <joint name="MFJ0" pos="0 0 0" axis="1 0 0" range="0 1.571" user="1104" limited="true" margin="0.01"
                         armature="0.001" damping="0.05" frictionloss="0.001"/>
                  <geom name="V_mfdistal" class="D_Vizual" mesh="F1"/>
                  <geom name="C_mfdistal" class="DC_Hand" size="0.00705 0.012" pos="0 0 0.012" type="capsule"
                        condim="4"/>
                  <site name="S_mftip" pos="0 0 0.026" group="3" size="0.005 0 0" rgba="0.4 0.9 0.4 1"/>
                  <site name="Tch_mftip" class="D_Touch" pos="0 -0.004 0.018"/>
                </body>
              </body>
            </body>
          </body>
          <body name="rfknuckle" pos="-0.011 0 0.095">
            <inertial pos="0 0 0" quat="0.520062 0.854102 0.00600072 -0.00300036" mass="0.008"
                      diaginertia="1e-05 1e-05 1e-05"/>
            <joint name="RFJ3" pos="0 0 0" axis="0 1 0" range="-0.436 0.436" user="1111" limited="true" margin="0.01"
                   armature="0.001" damping="0.05" frictionloss="0.001"/>
            <geom name="V_rfknuckle" class="D_Vizual" mesh="knuckle"/>
            <body name="rfproximal" pos="0 0 0">
              <inertial pos="0 0 0.023" quat="0.707095 -0.00400054 0.00400054 0.707095" mass="0.014"
                        diaginertia="1e-05 1e-05 1e-05"/>
              <joint name="RFJ2" pos="0 0 0" axis="1 0 0" range="0 1.571" user="1110" limited="true" margin="0.01"
                     armature="0.001" damping="0.05" frictionloss="0.001"/>
              <geom name="V_rfproximal" class="D_Vizual" mesh="F3"/>
              <geom name="C_rfproximal" class="DC_Hand" size="0.01 0.0225" pos="0 0 0.0225" type="capsule"/>
              <site name="Tch_rfproximal" class="D_Touch" pos="0 -0.007 0.022" size="0.009 0.004 0.012"/>
              <body name="rfmiddle" pos="0 0 0.045">
                <inertial pos="0 0 0.012" quat="0.707107 0 0 0.707107" mass="0.012" diaginertia="1e-05 1e-05 1e-05"/>
                <joint name="RFJ1" pos="0 0 0" axis="1 0 0" range="0 1.571" user="1109" limited="true" margin="0.01"
                       armature="0.001" damping="0.05" frictionloss="0.001"/>
                <geom name="V_rfmiddle" class="D_Vizual" mesh="F2"/>
                <geom name="C_rfmiddle" class="DC_Hand" size="0.00805 0.0125" pos="0 0 0.0125" type="capsule"/>
                <site name="Tch_rfmiddle" class="D_Touch" pos="0 -0.007 0.013" size="0.009 0.002 0.007"/>
                <body name="rfdistal" pos="0 0 0.025">
                  <inertial pos="0 0 0.015" quat="0.7071 -0.00300043 0.00300043 0.7071" mass="0.01"
                            diaginertia="1e-05 1e-05 1e-05"/>
                  <joint name="RFJ0" pos="0 0 0" axis="1 0 0" range="0 1.571" user="1108" limited="true" margin="0.01"
                         armature="0.001" damping="0.05" frictionloss="0.001"/>
                  <geom name="V_rfdistal" class="D_Vizual" pos="0 0 0.001" mesh="F1"/>
                  <geom name="C_rfdistal" class="DC_Hand" size="0.00705 0.012" pos="0 0 0.012" type="capsule"
                        condim="4"/>
                  <site name="S_rftip" pos="0 0 0.026" group="3" size="0.005 0 0" rgba="0.4 0.9 0.4 1"/>
                  <site name="Tch_rftip" class="D_Touch" pos="0 -0.004 0.018"/>
                </body>
              </body>
            </body>
          </body>
          <body name="lfmetacarpal" pos="-0.017 0 0.044">
            <inertial pos="-0.014 0.001 0.014" quat="0.709167 -0.0920216 -0.0630148 0.696164" mass="0.075"
                      diaginertia="1e-05 1e-05 1e-05"/>
            <joint name="LFJ4" pos="0 0 0" axis="0.570977 0 0.820966" range="0 0.698" user="1116" limited="true"
                   margin="0.01" armature="0.001" damping="0.05" frictionloss="0.001"/>
            <geom name="V_lfmetacarpal" class="D_Vizual" pos="-0.016 0 -0.023" mesh="lfmetacarpal"/>
            <!--            <geom name="C_lfmetacarpal" class="DC_Hand" size="0.0095 0.0111 0.025" pos="-0.0165 0 0.01" type="box"-->
            <!--                  rgba="0.4 0.5 0.6 0.2"/>-->
            <site name="Tch_lfmetacarpal" class="D_Touch" pos="-0.016 -0.008 0.017" size="0.009 0.004 0.014"/>
            <body name="lfknuckle" pos="-0.017 0 0.044">
              <inertial pos="0 0 0" quat="0.520062 0.854102 0.00600072 -0.00300036" mass="0.008"
                        diaginertia="1e-05 1e-05 1e-05"/>
              <joint name="LFJ3" pos="0 0 0" axis="0 1 0" range="-0.436 0.436" user="1115" limited="true" margin="0.01"
                     armature="0.001" damping="0.05" frictionloss="0.001"/>
              <geom name="V_lfknuckle" class="D_Vizual" mesh="knuckle"/>
              <body name="lfproximal" pos="0 0 0">
                <inertial pos="0 0 0.023" quat="0.707095 -0.00400054 0.00400054 0.707095" mass="0.014"
                          diaginertia="1e-05 1e-05 1e-05"/>
                <joint name="LFJ2" pos="0 0 0" axis="1 0 0" range="0 1.571" user="1114" limited="true" margin="0.01"
                       armature="0.001" damping="0.05" frictionloss="0.001"/>
                <geom name="V_lfproximal" class="D_Vizual" mesh="F3"/>
                <geom name="C_lfproximal" class="DC_Hand" size="0.01 0.0225" pos="0 0 0.0225" type="capsule"/>
                <site name="Tch_lfproximal" class="D_Touch" pos="0 -0.007 0.022" size="0.009 0.004 0.012"/>
                <body name="lfmiddle" pos="0 0 0.045">
                  <inertial pos="0 0 0.012" quat="0.707107 0 0 0.707107" mass="0.012" diaginertia="1e-05 1e-05 1e-05"/>
                  <joint name="LFJ1" pos="0 0 0" axis="1 0 0" range="0 1.571" user="1113" limited="true" margin="0.01"
                         armature="0.001" damping="0.05" frictionloss="0.001"/>
                  <geom name="V_lfmiddle" class="D_Vizual" mesh="F2"/>
                  <geom name="C_lfmiddle" class="DC_Hand" size="0.00805 0.0125" pos="0 0 0.0125" type="capsule"/>
                  <site name="Tch_lfmiddle" class="D_Touch" pos="0 -0.007 0.013" size="0.009 0.002 0.007"/>
                  <body name="lfdistal" pos="0 0 0.025">
                    <inertial pos="0 0 0.015" quat="0.7071 -0.00300043 0.00300043 0.7071" mass="0.01"
                              diaginertia="1e-05 1e-05 1e-05"/>
                    <joint name="LFJ0" pos="0 0 0" axis="1 0 0" range="0 1.571" user="1112" limited="true" margin="0.01"
                           armature="0.001" damping="0.05" frictionloss="0.001"/>
                    <geom name="V_lfdistal" class="D_Vizual" pos="0 0 0.001" mesh="F1"/>
                    <geom name="C_lfdistal" class="DC_Hand" size="0.00705 0.012" pos="0 0 0.012" type="capsule"
                          condim="4"/>
                    <site name="S_lftip" pos="0 0 0.026" group="3" size="0.005 0 0" rgba="0.4 0.9 0.4 1"/>
                    <site name="Tch_lftip" class="D_Touch" pos="0 -0.004 0.018"/>
                  </body>
                </body>
              </body>
            </body>
          </body>
          <body name="thbase" pos="0.034 -0.009 0.029" quat="0.923956 0 0.382499 0">
            <inertial pos="0 0 0" mass="0.01" diaginertia="1e-05 1e-05 1e-05"/>
            <joint name="THJ4" pos="0 0 0" axis="0 0 -1" range="-1.047 1.047" user="1121" limited="true" margin="0.01"
                   armature="0.001" damping="0.05" frictionloss="0.001"/>
            <geom name="V_thbase" size="0.001 0.001 0.001" type="box" group="1"/>
            <body name="thproximal" pos="0 0 0">
              <inertial pos="0 0 0.017" quat="0.981604 0 0.000999597 0.190923" mass="0.016"
                        diaginertia="1e-05 1e-05 1e-05"/>
              <joint name="THJ3" pos="0 0 0" axis="1 0 0" range="0 1.309" user="1120" limited="true" margin="0.01"
                     armature="0.001" damping="0.05" frictionloss="0.001"/>
              <geom name="V_thproximal" class="D_Vizual" mesh="TH3_z"/>
              <geom name="C_thproximal" class="DC_Hand" size="0.013 0.019" pos="0 0 0.019" type="capsule"
                    rgba="0.4 0.5 0.6 0.1"/>
              <site name="Tch_thproximal" class="D_Touch" pos="-0.008 0 0.022" size="0.005 0.011 0.011"/>
              <body name="thhub" pos="0 0 0.038">
                <inertial pos="0 0 0" mass="0.002" diaginertia="1e-05 1e-05 1e-05"/>
                <joint name="THJ2" pos="0 0 0" axis="1 0 0" range="-0.262 0.262" user="1119" limited="true"
                       margin="0.01" armature="0.001" damping="0.05" frictionloss="0.001"/>
                <geom name="V_thhub" size="0.001 0.001 0.001" type="box" group="1"/>
                <body name="thmiddle" pos="0 0 0">
                  <inertial pos="0 0 0.016" quat="0.999971 -0.000999971 -0.00699979 0.00299991" mass="0.016"
                            diaginertia="1e-05 1e-05 1e-05"/>
                  <joint name="THJ1" pos="0 0 0" axis="0 1 0" range="-0.524 0.524" user="1118" limited="true"
                         margin="0.01" armature="0.001" damping="0.05" frictionloss="0.001"/>
                  <geom name="V_thmiddle" class="D_Vizual" mesh="TH2_z"/>
                  <geom name="C_thmiddle" class="DC_Hand" size="0.011 0.016" pos="0 0 0.016" type="capsule"/>
                  <site name="Tch_thmiddle" class="D_Touch" pos="-0.008 0 0.018" size="0.005 0.011 0.011"/>
                  <body name="thdistal" pos="0 0 0.032">
                    <inertial pos="0 0 0.016" quat="0.99887 -0.00499935 -0.0469939 0.00499935" mass="0.016"
                              diaginertia="1e-05 1e-05 1e-05"/>
                    <joint name="THJ0" pos="0 0 0" axis="0 1 0" range="-1.571 0" user="1117" limited="true"
                           margin="0.01" armature="0.001" damping="0.05" frictionloss="0.001"/>
                    <geom name="V_thdistal" class="D_Vizual" mesh="TH1_z"/>
                    <geom name="C_thdistal" class="DC_Hand" size="0.00918 0.013" pos="0 0 0.013" type="capsule"
                          condim="4"/>
                    <site name="S_thtip" pos="0 0 0.0275" group="3" size="0.005 0 0" rgba="0.4 0.9 0.4 1"/>
                    <site name="Tch_thtip" class="D_Touch" pos="-0.005 0 0.02" size="0.005 0.011 0.016"/>
                  </body>
                </body>
              </body>
            </body>
          </body>
        </body>
      </body>
    </body>
  </worldbody>
  <contact>
    <pair geom1="C_palm0" geom2="C_thdistal" condim="1"/>
    <pair geom1="C_ffproximal" geom2="C_mfproximal" condim="1"/>
    <pair geom1="C_ffproximal" geom2="C_thdistal" condim="1"/>
    <pair geom1="C_ffmiddle" geom2="C_thdistal" condim="1"/>
    <pair geom1="C_ffdistal" geom2="C_mfdistal" condim="1"/>
    <pair geom1="C_ffdistal" geom2="C_thdistal" condim="1"/>
    <pair geom1="C_mfproximal" geom2="C_rfproximal" condim="1"/>
    <pair geom1="C_mfproximal" geom2="C_thdistal" condim="1"/>
    <pair geom1="C_mfdistal" geom2="C_rfdistal" condim="1"/>
    <pair geom1="C_mfdistal" geom2="C_lfdistal" condim="1"/>
    <pair geom1="C_mfdistal" geom2="C_thdistal" condim="1"/>
    <pair geom1="C_rfproximal" geom2="C_lfproximal" condim="1"/>
    <pair geom1="C_rfmiddle" geom2="C_lfmiddle" condim="1"/>
    <pair geom1="C_rfmiddle" geom2="C_lfdistal" condim="1"/>
    <pair geom1="C_rfdistal" geom2="C_lfmiddle" condim="1"/>
    <pair geom1="C_rfdistal" geom2="C_lfdistal" condim="1"/>
    <pair geom1="C_rfdistal" geom2="C_lfdistal" condim="1"/>
    <pair geom1="C_rfdistal" geom2="C_thdistal" condim="1"/>
    <pair geom1="C_lfdistal" geom2="C_thdistal" condim="1"/>
  </contact>
  <tendon>
    <fixed name="T_WRJ1r" range="-0.032 0.032" user="1236" limited="true">
      <joint joint="WRJ1" coef="0.018"/>
    </fixed>
    <fixed name="T_WRJ1l" range="-0.032 0.032" user="1237" limited="true">
      <joint joint="WRJ1" coef="-0.018"/>
    </fixed>
    <fixed name="T_WRJ0u" range="-0.032 0.032" user="1236" limited="true">
      <joint joint="WRJ0" coef="0.018"/>
    </fixed>
    <fixed name="T_WRJ0d" range="-0.032 0.032" user="1237" limited="true">
      <joint joint="WRJ0" coef="-0.018"/>
    </fixed>
    <fixed name="T_FFJ3r" range="-0.018 0.018" user="1204" limited="true">
      <joint joint="FFJ3" coef="0.01"/>
    </fixed>
    <fixed name="T_FFJ3l" range="-0.018 0.018" user="1205" limited="true">
      <joint joint="FFJ3" coef="-0.01"/>
    </fixed>
    <fixed name="T_FFJ2u" range="-0.007 0.03" user="1202" limited="true">
      <joint joint="FFJ2" coef="0.01"/>
    </fixed>
    <fixed name="T_FFJ2d" range="-0.03 0.007" user="1203" limited="true">
      <joint joint="FFJ2" coef="-0.01"/>
    </fixed>
    <fixed name="T_FFJ1c" range="-0.001 0.001" limited="true">
      <joint joint="FFJ0" coef="0.00705"/>
      <joint joint="FFJ1" coef="-0.00805"/>
    </fixed>
    <fixed name="T_FFJ1u" range="-0.007 0.03" user="1200" limited="true">
      <joint joint="FFJ0" coef="0.00705"/>
      <joint joint="FFJ1" coef="0.00805"/>
    </fixed>
    <fixed name="T_FFJ1d" range="-0.03 0.007" user="1201" limited="true">
      <joint joint="FFJ0" coef="-0.00705"/>
      <joint joint="FFJ1" coef="-0.00805"/>
    </fixed>
    <fixed name="T_MFJ3r" range="-0.018 0.018" user="1210" limited="true">
      <joint joint="MFJ3" coef="0.01"/>
    </fixed>
    <fixed name="T_MFJ3l" range="-0.018 0.018" user="1211" limited="true">
      <joint joint="MFJ3" coef="-0.01"/>
    </fixed>
    <fixed name="T_MFJ2u" range="-0.007 0.03" user="1208" limited="true">
      <joint joint="MFJ2" coef="0.01"/>
    </fixed>
    <fixed name="T_MFJ2d" range="-0.03 0.007" user="1209" limited="true">
      <joint joint="MFJ2" coef="-0.01"/>
    </fixed>
    <fixed name="T_MFJ1c" range="-0.001 0.001" limited="true">
      <joint joint="MFJ0" coef="0.00705"/>
      <joint joint="MFJ1" coef="-0.00805"/>
    </fixed>
    <fixed name="T_MFJ1u" range="-0.007 0.03" user="1206" limited="true">
      <joint joint="MFJ0" coef="0.00705"/>
      <joint joint="MFJ1" coef="0.00805"/>
    </fixed>
    <fixed name="T_MFJ1d" range="-0.03 0.007" user="1207" limited="true">
      <joint joint="MFJ0" coef="-0.00705"/>
      <joint joint="MFJ1" coef="-0.00805"/>
    </fixed>
    <fixed name="T_RFJ3r" range="-0.018 0.018" user="1216" limited="true">
      <joint joint="RFJ3" coef="0.01"/>
    </fixed>
    <fixed name="T_RFJ3l" range="-0.018 0.018" user="1217" limited="true">
      <joint joint="RFJ3" coef="-0.01"/>
    </fixed>
    <fixed name="T_RFJ2u" range="-0.007 0.03" user="1214" limited="true">
      <joint joint="RFJ2" coef="0.01"/>
    </fixed>
    <fixed name="T_RFJ2d" range="-0.03 0.007" user="1215" limited="true">
      <joint joint="RFJ2" coef="-0.01"/>
    </fixed>
    <fixed name="T_RFJ1c" range="-0.001 0.001" limited="true">
      <joint joint="RFJ0" coef="0.00705"/>
      <joint joint="RFJ1" coef="-0.00805"/>
    </fixed>
    <fixed name="T_RFJ1u" range="-0.007 0.03" user="1212" limited="true">
      <joint joint="RFJ0" coef="0.00705"/>
      <joint joint="RFJ1" coef="0.00805"/>
    </fixed>
    <fixed name="T_RFJ1d" range="-0.03 0.007" user="1213" limited="true">
      <joint joint="RFJ0" coef="-0.00705"/>
      <joint joint="RFJ1" coef="-0.00805"/>
    </fixed>
    <fixed name="T_LFJ4u" range="-0.007 0.03" user="1224" limited="true">
      <joint joint="LFJ4" coef="0.01"/>
    </fixed>
    <fixed name="T_LFJ4d" range="-0.03 0.007" user="1225" limited="true">
      <joint joint="LFJ4" coef="-0.01"/>
    </fixed>
    <fixed name="T_LFJ3r" range="-0.018 0.018" user="1222" limited="true">
      <joint joint="LFJ3" coef="0.01"/>
    </fixed>
    <fixed name="T_LFJ3l" range="-0.018 0.018" user="1223" limited="true">
      <joint joint="LFJ3" coef="-0.01"/>
    </fixed>
    <fixed name="T_LFJ2u" range="-0.007 0.03" user="1220" limited="true">
      <joint joint="LFJ2" coef="0.01"/>
    </fixed>
    <fixed name="T_LFJ2d" range="-0.03 0.007" user="1221" limited="true">
      <joint joint="LFJ2" coef="-0.01"/>
    </fixed>
    <fixed name="T_LFJ1c" range="-0.001 0.001" limited="true">
      <joint joint="LFJ0" coef="0.00705"/>
      <joint joint="LFJ1" coef="-0.00805"/>
    </fixed>
    <fixed name="T_LFJ1u" range="-0.007 0.03" user="1218" limited="true">
      <joint joint="LFJ0" coef="0.00705"/>
      <joint joint="LFJ1" coef="0.00805"/>
    </fixed>
    <fixed name="T_LFJ1d" range="-0.03 0.007" user="1219" limited="true">
      <joint joint="LFJ0" coef="-0.00705"/>
      <joint joint="LFJ1" coef="-0.00805"/>
    </fixed>
    <fixed name="T_THJ4a" range="-0.018 0.018" user="1234" limited="true">
      <joint joint="THJ4" coef="0.01636"/>
    </fixed>
    <fixed name="T_THJ4c" range="-0.018 0.018" user="1235" limited="true">
      <joint joint="THJ4" coef="-0.01636"/>
    </fixed>
    <fixed name="T_THJ3u" range="-0.007 0.03" user="1232" limited="true">
      <joint joint="THJ3" coef="0.01"/>
    </fixed>
    <fixed name="T_THJ3d" range="-0.03 0.007" user="1233" limited="true">
      <joint joint="THJ3" coef="-0.01"/>
    </fixed>
    <fixed name="T_THJ2u" range="-0.018 0.018" user="1230" limited="true">
      <joint joint="THJ2" coef="0.011"/>
    </fixed>
    <fixed name="T_THJ2d" range="-0.018 0.018" user="1231" limited="true">
      <joint joint="THJ2" coef="-0.011"/>
    </fixed>
    <fixed name="T_THJ1r" range="-0.018 0.018" user="1228" limited="true">
      <joint joint="THJ1" coef="0.011"/>
    </fixed>
    <fixed name="T_THJ1l" range="-0.018 0.018" user="1229" limited="true">
      <joint joint="THJ1" coef="-0.011"/>
    </fixed>
    <fixed name="T_THJ0r" range="-0.03 0.007" user="1226" limited="true">
      <joint joint="THJ0" coef="0.009"/>
    </fixed>
    <fixed name="T_THJ0l" range="-0.007 0.03" user="1227" limited="true">
      <joint joint="THJ0" coef="-0.009"/>
    </fixed>
  </tendon>
  <actuator>
    <general biasprm="0 -200 0 0 0 0 0 0 0 0" biastype="affine" ctrllimited="true" ctrlrange="-0.25 0.25"
             gainprm="500 0 0 0 0 0 0 0 0 0" joint="ARTx" name="A_ARTx"
             user="0 1 0.03 0.0939711 0.513477 0.0358776 1.23598 8.40409 0.485031 6.04244 1.02187 0.175297 0.121642 0 0 0"/>
    <general biasprm="0 -200 0 0 0 0 0 0 0 0" biastype="affine" ctrllimited="true" ctrlrange="0 0.2"
             gainprm="500 0 0 0 0 0 0 0 0 0" joint="ARTy" name="A_ARTy"
             user="0 1 0.03 0.0939711 0.513477 0.0358776 1.23598 8.40409 0.485031 6.04244 1.02187 0.175297 0.121642 0 0 0"/>
    <general biasprm="0 -200 0 0 0 0 0 0 0 0" biastype="affine" ctrllimited="true" ctrlrange="-0.3 0.5"
             gainprm="500 0 0 0 0 0 0 0 0 0" joint="ARTz" name="A_ARTz"
             user="0 1 0.03 0.0939711 0.513477 0.0358776 1.23598 8.40409 0.485031 6.04244 1.02187 0.175297 0.121642 0 0 0"/>
    <general biasprm="0 -200 0 0 0 0 0 0 0 0" biastype="affine" ctrllimited="true" ctrlrange="-0.75 0.75"
             gainprm="500 0 0 0 0 0 0 0 0 0" joint="ARRx" name="A_ARRx"
             user="0 1 0.03 0.0939711 0.513477 0.0358776 1.23598 8.40409 0.485031 6.04244 1.02187 0.175297 0.121642 0 0 0"/>
    <general biasprm="0 -200 0 0 0 0 0 0 0 0" biastype="affine" ctrllimited="true" ctrlrange="-0.75 0.75"
             gainprm="500 0 0 0 0 0 0 0 0 0" joint="ARRy" name="A_ARRy"
             user="0 1 0.03 0.0939711 0.513477 0.0358776 1.23598 8.40409 0.485031 6.04244 1.02187 0.175297 0.121642 0 0 0"/>
    <general biasprm="0 -200 0 0 0 0 0 0 0 0" biastype="affine" ctrllimited="true" ctrlrange="-0.75 0.75"
             gainprm="500 0 0 0 0 0 0 0 0 0" joint="ARRz" name="A_ARRz"
             user="0 1 0.03 0.0939711 0.513477 0.0358776 1.23598 8.40409 0.485031 6.04244 1.02187 0.175297 0.121642 0 0 0"/>
    <general biasprm="0 -10 0 0 0 0 0 0 0 0" biastype="affine" ctrllimited="true" ctrlrange="-0.524 0.175"
             gainprm="10 0 0 0 0 0 0 0 0 0" joint="WRJ1" name="A_WRJ1"
             user="1002 0 2001 -0.02 0.02 0 0 0 0 0 0 0 0 0 0 0"/>
    <general biasprm="0 -10 0 0 0 0 0 0 0 0" biastype="affine" ctrllimited="true" ctrlrange="-0.79 0.61"
             gainprm="10 0 0 0 0 0 0 0 0 0" joint="WRJ0" name="A_WRJ0"
             user="1002 0 2001 -0.02 0.02 0 0 0 0 0 0 0 0 0 0 0"/>
    <general biasprm="0 -1 0 0 0 0 0 0 0 0" biastype="affine" ctrllimited="true" ctrlrange="-0.44 0.44" joint="FFJ3"
             name="A_FFJ3" user="1002 0 2001 -0.1 0.1 0 0 0 0 0 0 0 0 0 0 0"/>
    <general biasprm="0 -1 0 0 0 0 0 0 0 0" biastype="affine" ctrllimited="true" ctrlrange="0 1.6" joint="FFJ2"
             name="A_FFJ2" user="1002 0 2001 -0.1 0.1 0 0 0 0 0 0 0 0 0 0 0"/>
    <general biasprm="0 -1 0 0 0 0 0 0 0 0" biastype="affine" ctrllimited="true" ctrlrange="0 1.6" joint="FFJ1"
             name="A_FFJ1" user="1002 0 2001 -0.1 0.1 0 0 0 0 0 0 0 0 0 0 0"/>
    <general biasprm="0 -1 0 0 0 0 0 0 0 0" biastype="affine" ctrllimited="true" ctrlrange="0 1.6" joint="FFJ0"
             name="A_FFJ0" user="1002 0 2001 -0.1 0.1 0 0 0 0 0 0 0 0 0 0 0"/>
    <general biasprm="0 -1 0 0 0 0 0 0 0 0" biastype="affine" ctrllimited="true" ctrlrange="-0.44 0.44" joint="MFJ3"
             name="A_MFJ3" user="1002 0 2001 -0.1 0.1 0 0 0 0 0 0 0 0 0 0 0"/>
    <general biasprm="0 -1 0 0 0 0 0 0 0 0" biastype="affine" ctrllimited="true" ctrlrange="0 1.6" joint="MFJ2"
             name="A_MFJ2" user="1002 0 2001 -0.1 0.1 0 0 0 0 0 0 0 0 0 0 0"/>
    <general biasprm="0 -1 0 0 0 0 0 0 0 0" biastype="affine" ctrllimited="true" ctrlrange="0 1.6" joint="MFJ1"
             name="A_MFJ1" user="1002 0 2001 -0.1 0.1 0 0 0 0 0 0 0 0 0 0 0"/>
    <general biasprm="0 -1 0 0 0 0 0 0 0 0" biastype="affine" ctrllimited="true" ctrlrange="0 1.6" joint="MFJ0"
             name="A_MFJ0" user="1002 0 2001 -0.1 0.1 0 0 0 0 0 0 0 0 0 0 0"/>
    <general biasprm="0 -1 0 0 0 0 0 0 0 0" biastype="affine" ctrllimited="true" ctrlrange="-0.44 0.44" joint="RFJ3"
             name="A_RFJ3" user="1002 0 2001 -0.1 0.1 0 0 0 0 0 0 0 0 0 0 0"/>
    <general biasprm="0 -1 0 0 0 0 0 0 0 0" biastype="affine" ctrllimited="true" ctrlrange="0 1.6" joint="RFJ2"
             name="A_RFJ2" user="1002 0 2001 -0.1 0.1 0 0 0 0 0 0 0 0 0 0 0"/>
    <general biasprm="0 -1 0 0 0 0 0 0 0 0" biastype="affine" ctrllimited="true" ctrlrange="0 1.6" joint="RFJ1"
             name="A_RFJ1" user="1002 0 2001 -0.1 0.1 0 0 0 0 0 0 0 0 0 0 0"/>
    <general biasprm="0 -1 0 0 0 0 0 0 0 0" biastype="affine" ctrllimited="true" ctrlrange="0 1.6" joint="RFJ0"
             name="A_RFJ0" user="1002 0 2001 -0.1 0.1 0 0 0 0 0 0 0 0 0 0 0"/>
    <general biasprm="0 -1 0 0 0 0 0 0 0 0" biastype="affine" ctrllimited="true" ctrlrange="0 0.7" joint="LFJ4"
             name="A_LFJ4" user="1002 0 2001 -0.1 0.1 0 0 0 0 0 0 0 0 0 0 0"/>
    <general biasprm="0 -1 0 0 0 0 0 0 0 0" biastype="affine" ctrllimited="true" ctrlrange="-0.44 0.44" joint="LFJ3"
             name="A_LFJ3" user="1002 0 2001 -0.1 0.1 0 0 0 0 0 0 0 0 0 0 0"/>
    <general biasprm="0 -1 0 0 0 0 0 0 0 0" biastype="affine" ctrllimited="true" ctrlrange="0 1.6" joint="LFJ2"
             name="A_LFJ2" user="1002 0 2001 -0.1 0.1 0 0 0 0 0 0 0 0 0 0 0"/>
    <general biasprm="0 -1 0 0 0 0 0 0 0 0" biastype="affine" ctrllimited="true" ctrlrange="0 1.6" joint="LFJ1"
             name="A_LFJ1" user="1002 0 2001 -0.1 0.1 0 0 0 0 0 0 0 0 0 0 0"/>
    <general biasprm="0 -1 0 0 0 0 0 0 0 0" biastype="affine" ctrllimited="true" ctrlrange="0 1.6" joint="LFJ0"
             name="A_LFJ0" user="1002 0 2001 -0.1 0.1 0 0 0 0 0 0 0 0 0 0 0"/>
    <general biasprm="0 -1 0 0 0 0 0 0 0 0" biastype="affine" ctrllimited="true" ctrlrange="-1 1" joint="THJ4"
             name="A_THJ4" user="1002 0 2001 -0.1 0.1 0 0 0 0 0 0 0 0 0 0 0"/>
    <general biasprm="0 -1 0 0 0 0 0 0 0 0" biastype="affine" ctrllimited="true" ctrlrange="0 1.3" joint="THJ3"
             name="A_THJ3" user="1002 0 2001 -0.1 0.1 0 0 0 0 0 0 0 0 0 0 0"/>
    <general biasprm="0 -1 0 0 0 0 0 0 0 0" biastype="affine" ctrllimited="true" ctrlrange="-0.26 0.26" joint="THJ2"
             name="A_THJ2" user="1002 0 2001 -0.1 0.1 0 0 0 0 0 0 0 0 0 0 0"/>
    <general biasprm="0 -1 0 0 0 0 0 0 0 0" biastype="affine" ctrllimited="true" ctrlrange="-0.52 0.52" joint="THJ1"
             name="A_THJ1" user="1002 0 2001 -0.1 0.1 0 0 0 0 0 0 0 0 0 0 0"/>
    <general biasprm="0 -1 0 0 0 0 0 0 0 0" biastype="affine" ctrllimited="true" ctrlrange="-1.571 0" joint="THJ0"
             name="A_THJ0" user="1002 0 2001 -0.1 0.1 0 0 0 0 0 0 0 0 0 0 0"/>
  </actuator>
  <sensor>
    <actuatorfrc actuator="A_WRJ1" name="Saf_A_WRJ1"/>
    <actuatorfrc actuator="A_WRJ0" name="Saf_A_WRJ0"/>
    <actuatorfrc actuator="A_FFJ3" name="Saf_A_FFJ3"/>
    <actuatorfrc actuator="A_FFJ2" name="Saf_A_FFJ2"/>
    <actuatorfrc actuator="A_FFJ1" name="Saf_A_FFJ1"/>
    <actuatorfrc actuator="A_MFJ3" name="Saf_A_MFJ3"/>
    <actuatorfrc actuator="A_MFJ2" name="Saf_A_MFJ2"/>
    <actuatorfrc actuator="A_MFJ1" name="Saf_A_MFJ1"/>
    <actuatorfrc actuator="A_RFJ3" name="Saf_A_RFJ3"/>
    <actuatorfrc actuator="A_RFJ2" name="Saf_A_RFJ2"/>
    <actuatorfrc actuator="A_RFJ1" name="Saf_A_RFJ1"/>
    <actuatorfrc actuator="A_LFJ4" name="Saf_A_LFJ4"/>
    <actuatorfrc actuator="A_LFJ3" name="Saf_A_LFJ3"/>
    <actuatorfrc actuator="A_LFJ2" name="Saf_A_LFJ2"/>
    <actuatorfrc actuator="A_LFJ1" name="Saf_A_LFJ1"/>
    <actuatorfrc actuator="A_THJ4" name="Saf_A_THJ4"/>
    <actuatorfrc actuator="A_THJ3" name="Saf_A_THJ3"/>
    <actuatorfrc actuator="A_THJ2" name="Saf_A_THJ2"/>
    <actuatorfrc actuator="A_THJ1" name="Saf_A_THJ1"/>
    <actuatorfrc actuator="A_THJ0" name="Saf_A_THJ0"/>
    <touch site="Tch_fftip" name="ST_Tch_fftip"/>
    <touch site="Tch_mftip" name="ST_Tch_mftip"/>
    <touch site="Tch_rftip" name="ST_Tch_rftip"/>
    <touch site="Tch_lftip" name="ST_Tch_lftip"/>
    <touch site="Tch_thtip" name="ST_Tch_thtip"/>
    <touch site="Tch_ffmiddle" name="ST_Tch_ffmiddle"/>
    <touch site="Tch_mfmiddle" name="ST_Tch_mfmiddle"/>
    <touch site="Tch_rfmiddle" name="ST_Tch_rfmiddle"/>
    <touch site="Tch_lfmiddle" name="ST_Tch_lfmiddle"/>
    <touch site="Tch_thmiddle" name="ST_Tch_thmiddle"/>
    <touch site="Tch_ffproximal" name="ST_Tch_ffproximal"/>
    <touch site="Tch_mfproximal" name="ST_Tch_mfproximal"/>
    <touch site="Tch_rfproximal" name="ST_Tch_rfproximal"/>
    <touch site="Tch_lfproximal" name="ST_Tch_lfproximal"/>
    <touch site="Tch_thproximal" name="ST_Tch_thproximal"/>
    <touch site="Tch_ffmetacarpal" name="ST_Tch_ffmetacarpal"/>
    <touch site="Tch_mfmetacarpal" name="ST_Tch_mfmetacarpal"/>
    <touch site="Tch_rfmetacarpal" name="ST_Tch_rfmetacarpal"/>
    <touch site="Tch_lfmetacarpal" name="ST_Tch_lfmetacarpal"/>
    <touch site="Tch_thmetacarpal" name="ST_Tch_thmetacarpal"/>
    <touch site="Tch_palm" name="ST_Tch_palm"/>
    <jointpos joint="WRJ1" name="Sjp_WRJ1"/>
    <jointpos joint="WRJ0" name="Sjp_WRJ0"/>
    <jointpos joint="FFJ3" name="Sjp_FFJ3"/>
    <jointpos joint="FFJ2" name="Sjp_FFJ2"/>
    <jointpos joint="FFJ1" name="Sjp_FFJ1"/>
    <jointpos joint="FFJ0" name="Sjp_FFJ0"/>
    <jointpos joint="MFJ3" name="Sjp_MFJ3"/>
    <jointpos joint="MFJ2" name="Sjp_MFJ2"/>
    <jointpos joint="MFJ1" name="Sjp_MFJ1"/>
    <jointpos joint="MFJ0" name="Sjp_MFJ0"/>
    <jointpos joint="RFJ3" name="Sjp_RFJ3"/>
    <jointpos joint="RFJ2" name="Sjp_RFJ2"/>
    <jointpos joint="RFJ1" name="Sjp_RFJ1"/>
    <jointpos joint="RFJ0" name="Sjp_RFJ0"/>
    <jointpos joint="LFJ4" name="Sjp_LFJ4"/>
    <jointpos joint="LFJ3" name="Sjp_LFJ3"/>
    <jointpos joint="LFJ2" name="Sjp_LFJ2"/>
    <jointpos joint="LFJ1" name="Sjp_LFJ1"/>
    <jointpos joint="LFJ0" name="Sjp_LFJ0"/>
    <jointpos joint="THJ4" name="Sjp_THJ4"/>
    <jointpos joint="THJ3" name="Sjp_THJ3"/>
    <jointpos joint="THJ2" name="Sjp_THJ2"/>
    <jointpos joint="THJ1" name="Sjp_THJ1"/>
    <jointpos joint="THJ0" name="Sjp_THJ0"/>
  </sensor>
</mujoco>
